Workbook

Sheet kpdwfs_results
A1: filename | B1: scenario | C1: type | D1: n | E1: instance | F1: dp_obj | G1: dp_time | H1: gurobi_obj | I1: gurobi_time | J1: obj_match
A2: kpdwfs_sc3_id4_n1000_b1550_sets113_k1072_fully-correlated.txt | B2: 3 | C2: FC | D2: 1000 | E2: 4 | F2: 4588 | G2: 148.0427 | H2: 4588 | I2: 3545.2772 | J2: TRUE
A3: kpdwfs_sc4_id1_n800_b1240_sets38_k848_correlated.txt | B3: 4 | C3: C | D3: 800 | E3: 1 | F3: 3520 | G3: 57.3348 | H3: 3520 | I3: 355.3018 | J3: TRUE
A4: kpdwfs_sc4_id7_n700_b1085_sets39_k752_correlated.txt | B4: 4 | C4: C | D4: 700 | E4: 7 | F4: 3265 | G4: 21.5667 | H4: 3265 | I4: 48.1196 | J4: TRUE
A5: kpdwfs_sc3_id1_n1000_b1550_sets89_k1072_correlated.txt | B5: 3 | C5: C | D5: 1000 | E5: 1 | F5: 4620 | G5: 164.2619 | H5: 4620 | I5: 45.5603 | J5: TRUE
A6: kpdwfs_sc4_id1_n700_b1085_sets36_k752_fully-correlated.txt | B6: 4 | C6: FC | D6: 700 | E6: 1 | F6: 3302 | G6: 24.4143 | H6: 3302 | I6: 16.1076 | J6: TRUE
A7: kpdwfs_sc4_id9_n700_b1085_sets38_k752_correlated.txt | B7: 4 | C7: C | D7: 700 | E7: 9 | F7: 3265 | G7: 22.939 | H7: 3265 | I7: 3.2859 | J7: TRUE
A8: kpdwfs_sc3_id1_n1000_b1550_sets88_k1072_fully-correlated.txt | B8: 3 | C8: FC | D8: 1000 | E8: 1 | F8: 4566 | G8: 159.162 | H8: 4566 | I8: 1.7575 | J8: TRUE
A9: kpdwfs_sc4_id5_n1000_b1550_sets39_k1072_correlated.txt | B9: 4 | C9: C | D9: 1000 | E9: 5 | F9: 4690 | G9: 126.186 | H9: 4690 | I9: 1.4206 | J9: TRUE
A10: kpdwfs_sc4_id4_n500_b775_sets44_k528_fully-correlated.txt | B10: 4 | C10: FC | D10: 500 | E10: 4 | F10: 2245 | G10: 6.9871 | H10: 2245 | I10: 1.122 | J10: TRUE
A11: kpdwfs_sc4_id2_n1000_b1550_sets42_k1072_correlated.txt | B11: 4 | C11: C | D11: 1000 | E11: 2 | F11: 4410 | G11: 133.3204 | H11: 4410 | I11: 0.9672 | J11: TRUE
A12: kpdwfs_sc4_id4_n1000_b1550_sets53_k1072_fully-correlated.txt | B12: 4 | C12: FC | D12: 1000 | E12: 4 | F12: 4570 | G12: 141.6293 | H12: 4570 | I12: 0.8955 | J12: TRUE
A13: kpdwfs_sc3_id8_n700_b1085_sets88_k752_correlated.txt | B13: 3 | C13: C | D13: 700 | E13: 8 | F13: 3139 | G13: 22.4284 | H13: 3139 | I13: 0.8357 | J13: TRUE
... A599: kpdwfs_sc4_id10_n300_b465_sets30_k320_fully-correlated.txt | B599: 4 | C599: FC | D599: 300 | E599: 10 | F599: 1345 | G599: 0.7733 | H599: 1345 | I599: 0.005 | J599: TRUE
A600: kpdwfs_sc4_id1_n1000_b1550_sets40_k1072_correlated.txt | B600: 4 | C600: C | D600: 1000 | E600: 1 | F600: 4640 | G600: 147.611 | J600: FALSE
A601: kpdwfs_sc4_id6_n800_b1240_sets36_k848_correlated.txt | B601: 4 | C601: C | D601: 800 | E601: 6 | F601: 3570 | G601: 62.7664 | J601: FALSE

Sheet Analysis
A1: DP vs Gurobi — Comparison Analysis
A3: 1. OBJECTIVE VALUE CHECK
A4: Total instances compared: | B4: =COUNTA(kpdwfs_results!A2:A601) -> 600
A5: Mismatches found: | B5: {=SUMPRODUCT(--(kpdwfs_results!J2:J601<>TRUE))} -> 2
A6: Verdict: | B6: =IF(B5=0,"✅ All objective values are identical","⚠️ "&B5&" mismatches found") -> ⚠️ 2 mismatches found
A8: 2. OVERALL RUNTIME COMPARISON
A9: Solver | B9: Mean (s) | C9: Median (s) | D9: Std Dev (s) | E9: Min (s) | F9: Max (s) | G9: N
A10: DP | B10: =AVERAGE(kpdwfs_results!G2:G601) -> 27.157746 | C10: =MEDIAN(kpdwfs_results!G2:G601) -> 5.8207 | D10: =STDEV(kpdwfs_results!G2:G601) -> 45.062278 | E10: =MIN(kpdwfs_results!G2:G601) -> 0.3444 | F10: =MAX(kpdwfs_results!G2:G601) -> 179.4152 | G10: =COUNT(kpdwfs_results!G2:G601) -> 600
A11: Gurobi | B11: =AVERAGE(kpdwfs_results!I2:I601) -> 6.7764662 | C11: =MEDIAN(kpdwfs_results!I2:I601) -> 0.04055 | D11: =STDEV(kpdwfs_results!I2:I601) -> 145.69445 | E11: =MIN(kpdwfs_results!I2:I601) -> 0.005 | F11: =MAX(kpdwfs_results!I2:I601) -> 3545.2772 | G11: =COUNT(kpdwfs_results!I2:I601) -> 598
A12: Speedup (DP/Gurobi) | B12: =B10/B11 -> 4.0076561 | C12: =C10/C11 -> 143.54377
A14: 3. RUNTIME BY SCENARIO
A15: Scenario | B15: Count | C15: DP Mean (s) | D15: DP Median (s) | E15: Gurobi Mean (s) | F15: Gurobi Median (s) | G15: Speedup Mean | H15: Speedup Median
A16: scenario 1 | B16: =COUNTIF(kpdwfs_results!$B$2:$B$601,1) -> 150 | C16: =AVERAGEIF(kpdwfs_results!$B$2:$B$601,1,kpdwfs_results!$G$2:$G$601) -> 6.1476113 | D16: {=IFERROR(_xlfn.AGGREGATE(17,6,kpdwfs_results!$G$2:$G$601/(kpdwfs_results!$B$2:$B$601=1),2),"")} -> 5.2171 | E16: =AVERAGEIF(kpdwfs_results!$B$2:$B$601,1,kpdwfs_results!$I$2:$I$601) -> 0.076461333 | F16: {=IFERROR(_xlfn.AGGREGATE(17,6,kpdwfs_results!$I$2:$I$601/(kpdwfs_results!$B$2:$B$601=1),2),"")} -> 0.0746 | G16: =C16/E16 -> 80.401571 | H16: =D16/F16 -> 69.934316
A17: scenario 2 | B17: =COUNTIF(kpdwfs_results!$B$2:$B$601,2) -> 150 | C17: =AVERAGEIF(kpdwfs_results!$B$2:$B$601,2,kpdwfs_results!$G$2:$G$601) -> 3.7086107 | D17: {=IFERROR(_xlfn.AGGREGATE(17,6,kpdwfs_results!$G$2:$G$601/(kpdwfs_results!$B$2:$B$601=2),2),"")} -> 3.65965 | E17: =AVERAGEIF(kpdwfs_results!$B$2:$B$601,2,kpdwfs_results!$I$2:$I$601) -> 0.047152 | F17: {=IFERROR(_xlfn.AGGREGATE(17,6,kpdwfs_results!$I$2:$I$601/(kpdwfs_results!$B$2:$B$601=2),2),"")} -> 0.0437 | G17: =C17/E17 -> 78.652245 | H17: =D17/F17 -> 83.744851
A18: scenario 3 | B18: =COUNTIF(kpdwfs_results!$B$2:$B$601,3) -> 150 | C18: =AVERAGEIF(kpdwfs_results!$B$2:$B$601,3,kpdwfs_results!$G$2:$G$601) -> 52.047583 | D18: {=IFERROR(_xlfn.AGGREGATE(17,6,kpdwfs_results!$G$2:$G$601/(kpdwfs_results!$B$2:$B$601=3),2),"")} -> 23.8719 | E18: =AVERAGEIF(kpdwfs_results!$B$2:$B$601,3,kpdwfs_results!$I$2:$I$601) -> 23.996766 | F18: {=IFERROR(_xlfn.AGGREGATE(17,6,kpdwfs_results!$I$2:$I$601/(kpdwfs_results!$B$2:$B$601=3),2),"")} -> 0.0321 | G18: =C18/E18 -> 2.1689415 | H18: =D18/F18 -> 743.6729
A19: scenario 4 | B19: =COUNTIF(kpdwfs_results!$B$2:$B$601,4) -> 150 | C19: =AVERAGEIF(kpdwfs_results!$B$2:$B$601,4,kpdwfs_results!$G$2:$G$601) -> 46.727179 | D19: {=IFERROR(_xlfn.AGGREGATE(17,6,kpdwfs_results!$G$2:$G$601/(kpdwfs_results!$B$2:$B$601=4),2),"")} -> 22.8555 | E19: =AVERAGEIF(kpdwfs_results!$B$2:$B$601,4,kpdwfs_results!$I$2:$I$601) -> 2.9342561 | F19: {=IFERROR(_xlfn.AGGREGATE(17,6,kpdwfs_results!$I$2:$I$601/(kpdwfs_results!$B$2:$B$601=4),2),"")} -> 0.0266 | G19: =C19/E19 -> 15.924711 | H19: =D19/F19 -> 859.22932
A21: 4. RUNTIME BY CORRELATION TYPE
A22: Correlation Type | B22: Count | C22: DP Mean (s) | D22: DP Median (s) | E22: Gurobi Mean (s) | F22: Gurobi Median (s) | G22: Speedup Mean | H22: Speedup Median
A23: correlated | B23: =COUNTIF(kpdwfs_results!$C$2:$C$601,"C") -> 200 | C23: =AVERAGEIF(kpdwfs_results!$C$2:$C$601,"C",kpdwfs_results!$G$2:$G$601) -> 27.493286 | D23: {=IFERROR(_xlfn.AGGREGATE(17,6,kpdwfs_results!$G$2:$G$601/(kpdwfs_results!$C$2:$C$601="C"),2),"")} -> 5.95915 | E23: =AVERAGEIF(kpdwfs_results!$C$2:$C$601,"C",kpdwfs_results!$I$2:$I$601) -> 2.3609939 | F23: {=IFERROR(_xlfn.AGGREGATE(17,6,kpdwfs_results!$I$2:$I$601/(kpdwfs_results!$C$2:$C$601="C"),2),"")} -> 0.046 | G23: =C23/E23 -> 11.644793 | H23: =D23/F23 -> 129.54674
A24: fully-correlated | B24: =COUNTIF(kpdwfs_results!$C$2:$C$601,"FC") -> 200 | C24: =AVERAGEIF(kpdwfs_results!$C$2:$C$601,"FC",kpdwfs_results!$G$2:$G$601) -> 27.032027 | D24: {=IFERROR(_xlfn.AGGREGATE(17,6,kpdwfs_results!$G$2:$G$601/(kpdwfs_results!$C$2:$C$601="FC"),2),"")} -> 6.0133 | E24: =AVERAGEIF(kpdwfs_results!$C$2:$C$601,"FC",kpdwfs_results!$I$2:$I$601) -> 17.884294 | F24: {=IFERROR(_xlfn.AGGREGATE(17,6,kpdwfs_results!$I$2:$I$601/(kpdwfs_results!$C$2:$C$601="FC"),2),"")} -> 0.0456 | G24: =C24/E24 -> 1.5114953 | H24: =D24/F24 -> 131.87061
A25: not-correlated | B25: =COUNTIF(kpdwfs_results!$C$2:$C$601,"NC") -> 200 | C25: =AVERAGEIF(kpdwfs_results!$C$2:$C$601,"NC",kpdwfs_results!$G$2:$G$601) -> 26.947925 | D25: {=IFERROR(_xlfn.AGGREGATE(17,6,kpdwfs_results!$G$2:$G$601/(kpdwfs_results!$C$2:$C$601="NC"),2),"")} -> 5.6934 | E25: =AVERAGEIF(kpdwfs_results!$C$2:$C$601,"NC",kpdwfs_results!$I$2:$I$601) -> 0.0399555 | F25: {=IFERROR(_xlfn.AGGREGATE(17,6,kpdwfs_results!$I$2:$I$601/(kpdwfs_results!$C$2:$C$601="NC"),2),"")} -> 0.0317 | G25: =C25/E25 -> 674.44845 | H25: =D25/F25 -> 179.60252
A27: 5. RUNTIME BY SCENARIO × CORRELATION TYPE
A29: DP Mean Runtime (s)
B30: correlated | C30: fully-correlated | D30: not-correlated
A31: scenario 1 | B31: =AVERAGEIFS(kpdwfs_results!$G$2:$G$601,kpdwfs_results!$B$2:$B$601,1,kpdwfs_results!$C$2:$C$601,"C") -> 5.926764 | C31: =AVERAGEIFS(kpdwfs_results!$G$2:$G$601,kpdwfs_results!$B$2:$B$601,1,kpdwfs_results!$C$2:$C$601,"FC") -> 6.400408 | D31: =AVERAGEIFS(kpdwfs_results!$G$2:$G$601,kpdwfs_results!$B$2:$B$601,1,kpdwfs_results!$C$2:$C$601,"NC") -> 6.115662
A32: scenario 2 | B32: =AVERAGEIFS(kpdwfs_results!$G$2:$G$601,kpdwfs_results!$B$2:$B$601,2,kpdwfs_results!$C$2:$C$601,"C") -> 3.68902 | C32: =AVERAGEIFS(kpdwfs_results!$G$2:$G$601,kpdwfs_results!$B$2:$B$601,2,kpdwfs_results!$C$2:$C$601,"FC") -> 3.85743 | D32: =AVERAGEIFS(kpdwfs_results!$G$2:$G$601,kpdwfs_results!$B$2:$B$601,2,kpdwfs_results!$C$2:$C$601,"NC") -> 3.579382
A33: scenario 3 | B33: =AVERAGEIFS(kpdwfs_results!$G$2:$G$601,kpdwfs_results!$B$2:$B$601,3,kpdwfs_results!$C$2:$C$601,"C") -> 55.111504 | C33: =AVERAGEIFS(kpdwfs_results!$G$2:$G$601,kpdwfs_results!$B$2:$B$601,3,kpdwfs_results!$C$2:$C$601,"FC") -> 50.49689 | D33: =AVERAGEIFS(kpdwfs_results!$G$2:$G$601,kpdwfs_results!$B$2:$B$601,3,kpdwfs_results!$C$2:$C$601,"NC") -> 50.534354
A34: scenario 4 | B34: =AVERAGEIFS(kpdwfs_results!$G$2:$G$601,kpdwfs_results!$B$2:$B$601,4,kpdwfs_results!$C$2:$C$601,"C") -> 45.245858 | C34: =AVERAGEIFS(kpdwfs_results!$G$2:$G$601,kpdwfs_results!$B$2:$B$601,4,kpdwfs_results!$C$2:$C$601,"FC") -> 47.373378 | D34: =AVERAGEIFS(kpdwfs_results!$G$2:$G$601,kpdwfs_results!$B$2:$B$601,4,kpdwfs_results!$C$2:$C$601,"NC") -> 47.562302
A36: Gurobi Mean Runtime (s)
B37: correlated | C37: fully-correlated | D37: not-correlated
A38: scenario 1 | B38: =AVERAGEIFS(kpdwfs_results!$I$2:$I$601,kpdwfs_results!$B$2:$B$601,1,kpdwfs_results!$C$2:$C$601,"C") -> 0.088546 | C38: =AVERAGEIFS(kpdwfs_results!$I$2:$I$601,kpdwfs_results!$B$2:$B$601,1,kpdwfs_results!$C$2:$C$601,"FC") -> 0.074922 | D38: =AVERAGEIFS(kpdwfs_results!$I$2:$I$601,kpdwfs_results!$B$2:$B$601,1,kpdwfs_results!$C$2:$C$601,"NC") -> 0.065916
A39: scenario 2 | B39: =AVERAGEIFS(kpdwfs_results!$I$2:$I$601,kpdwfs_results!$B$2:$B$601,2,kpdwfs_results!$C$2:$C$601,"C") -> 0.049426 | C39: =AVERAGEIFS(kpdwfs_results!$I$2:$I$601,kpdwfs_results!$B$2:$B$601,2,kpdwfs_results!$C$2:$C$601,"FC") -> 0.044282 | D39: =AVERAGEIFS(kpdwfs_results!$I$2:$I$601,kpdwfs_results!$B$2:$B$601,2,kpdwfs_results!$C$2:$C$601,"NC") -> 0.047748
A40: scenario 3 | B40: =AVERAGEIFS(kpdwfs_results!$I$2:$I$601,kpdwfs_results!$B$2:$B$601,3,kpdwfs_results!$C$2:$C$601,"C") -> 0.97337 | C40: =AVERAGEIFS(kpdwfs_results!$I$2:$I$601,kpdwfs_results!$B$2:$B$601,3,kpdwfs_results!$C$2:$C$601,"FC") -> 70.992322 | D40: =AVERAGEIFS(kpdwfs_results!$I$2:$I$601,kpdwfs_results!$B$2:$B$601,3,kpdwfs_results!$C$2:$C$601,"NC") -> 0.024606
A41: scenario 4 | B41: =AVERAGEIFS(kpdwfs_results!$I$2:$I$601,kpdwfs_results!$B$2:$B$601,4,kpdwfs_results!$C$2:$C$601,"C") -> 8.5814521 | C41: =AVERAGEIFS(kpdwfs_results!$I$2:$I$601,kpdwfs_results!$B$2:$B$601,4,kpdwfs_results!$C$2:$C$601,"FC") -> 0.425652 | D41: =AVERAGEIFS(kpdwfs_results!$I$2:$I$601,kpdwfs_results!$B$2:$B$601,4,kpdwfs_results!$C$2:$C$601,"NC") -> 0.021552
A43: Speedup (DP/Gurobi)
B44: correlated | C44: fully-correlated | D44: not-correlated
A45: scenario 1 | B45: =B31/B38 -> 66.934294 | C45: =C31/C38 -> 85.427618 | D45: =D31/D38 -> 92.779629
A46: scenario 2 | B46: =B32/B39 -> 74.637235 | C46: =C32/C39 -> 87.110564 | D46: =D32/D39 -> 74.964019
A47: scenario 3 | B47: =B33/B40 -> 56.619275 | C47: =C33/C40 -> 0.71130072 | D47: =D33/D40 -> 2053.7411
A48: scenario 4 | B48: =B34/B41 -> 5.2725177 | C48: =C34/C41 -> 111.29603 | D48: =D34/D41 -> 2206.8626
...
