Workbook

Sheet results_dp
A1: scenario | B1: corr_type | C1: instance_file | D1: n | E1: obj_value | F1: runtime
A2: scenario 1 | B2: correlated | C2: scen_1id_10_objs_1000_size_1550_sets_89_k_18_correlated.txt | D2: 1000 | E2: 2602 | F2: 4.32
A3: scenario 1 | B3: correlated | C3: scen_1id_10_objs_300_size_465_sets_77_k_20_correlated.txt | D3: 300 | E3: 1271 | F3: 0.07
A4: scenario 1 | B4: correlated | C4: scen_1id_10_objs_500_size_775_sets_83_k_20_correlated.txt | D4: 500 | E4: 1767 | F4: 0.42
A5: scenario 1 | B5: correlated | C5: scen_1id_10_objs_700_size_1085_sets_91_k_20_correlated.txt | D5: 700 | E5: 2175 | F5: 1.52
A6: scenario 1 | B6: correlated | C6: scen_1id_10_objs_800_size_1240_sets_94_k_18_correlated.txt | D6: 800 | E6: 2342 | F6: 2.04
A7: scenario 1 | B7: correlated | C7: scen_1id_1_objs_1000_size_1550_sets_89_k_18_correlated.txt | D7: 1000 | E7: 2602 | F7: 4.07
A8: scenario 1 | B8: correlated | C8: scen_1id_1_objs_300_size_465_sets_74_k_20_correlated.txt | D8: 300 | E8: 1174 | F8: 0.07
A9: scenario 1 | B9: correlated | C9: scen_1id_1_objs_500_size_775_sets_78_k_20_correlated.txt | D9: 500 | E9: 1732 | F9: 0.46
A10: scenario 1 | B10: correlated | C10: scen_1id_1_objs_700_size_1085_sets_82_k_20_correlated.txt | D10: 700 | E10: 2085 | F10: 1.49
A11: scenario 1 | B11: correlated | C11: scen_1id_1_objs_800_size_1240_sets_93_k_18_correlated.txt | D11: 800 | E11: 2332 | F11: 2.09
A12: scenario 1 | B12: correlated | C12: scen_1id_2_objs_1000_size_1550_sets_96_k_18_correlated.txt | D12: 1000 | E12: 2672 | F12: 3.93
A13: scenario 1 | B13: correlated | C13: scen_1id_2_objs_300_size_465_sets_79_k_20_correlated.txt | D13: 300 | E13: 1258 | F13: 0.07
... A601: scenario 4 | B601: not-correlated | C601: scen_4id_9_objs_800_size_1240_sets_41_k_53_not-correlated.txt | D601: 800 | E601: 4045 | F601: 8.6

Sheet results_gurobi
A1: scenario | B1: corr_type | C1: instance_file | D1: n | E1: obj_value | F1: runtime
A2: scenario 1 | B2: correlated | C2: scen_1id_10_objs_1000_size_1550_sets_89_k_18_correlated.txt | D2: 1000 | E2: 2602 | F2: 0.05
A3: scenario 1 | B3: correlated | C3: scen_1id_10_objs_300_size_465_sets_77_k_20_correlated.txt | D3: 300 | E3: 1271 | F3: 0.01
A4: scenario 1 | B4: correlated | C4: scen_1id_10_objs_500_size_775_sets_83_k_20_correlated.txt | D4: 500 | E4: 1767 | F4: 0.01
A5: scenario 1 | B5: correlated | C5: scen_1id_10_objs_700_size_1085_sets_91_k_20_correlated.txt | D5: 700 | E5: 2175 | F5: 0.01
A6: scenario 1 | B6: correlated | C6: scen_1id_10_objs_800_size_1240_sets_94_k_18_correlated.txt | D6: 800 | E6: 2342 | F6: 0.01
A7: scenario 1 | B7: correlated | C7: scen_1id_1_objs_1000_size_1550_sets_89_k_18_correlated.txt | D7: 1000 | E7: 2602 | F7: 0.01
A8: scenario 1 | B8: correlated | C8: scen_1id_1_objs_300_size_465_sets_74_k_20_correlated.txt | D8: 300 | E8: 1174 | F8: 0.01
A9: scenario 1 | B9: correlated | C9: scen_1id_1_objs_500_size_775_sets_78_k_20_correlated.txt | D9: 500 | E9: 1732 | F9: 0.01
A10: scenario 1 | B10: correlated | C10: scen_1id_1_objs_700_size_1085_sets_82_k_20_correlated.txt | D10: 700 | E10: 2085 | F10: 0.01
A11: scenario 1 | B11: correlated | C11: scen_1id_1_objs_800_size_1240_sets_93_k_18_correlated.txt | D11: 800 | E11: 2332 | F11: 0.01
A12: scenario 1 | B12: correlated | C12: scen_1id_2_objs_1000_size_1550_sets_96_k_18_correlated.txt | D12: 1000 | E12: 2672 | F12: 0.01
A13: scenario 1 | B13: correlated | C13: scen_1id_2_objs_300_size_465_sets_79_k_20_correlated.txt | D13: 300 | E13: 1258 | F13: 0
... A601: scenario 4 | B601: not-correlated | C601: scen_4id_9_objs_800_size_1240_sets_41_k_53_not-correlated.txt | D601: 800 | E601: 4045 | F601: 0.01

Sheet results_gurobi_test
A1: scenario | B1: corr_type | C1: instance_file | D1: n | E1: obj_value | F1: runtime
A2: scenario 1 | B2: correlated | C2: scen_1id_10_objs_1000_size_1550_sets_89_k_18_correlated.txt | D2: 1000 | E2: 2602.0 | F2: 0.02
A3: scenario 1 | B3: correlated | C3: scen_1id_10_objs_300_size_465_sets_77_k_20_correlated.txt | D3: 300 | E3: 1.2713333e+16 | F3: 0.00
A4: scenario 1 | B4: correlated | C4: scen_1id_10_objs_500_size_775_sets_83_k_20_correlated.txt | D4: 500 | E4: 1.7672308e+15 | F4: 0.00
A5: scenario 1 | B5: correlated | C5: scen_1id_10_objs_700_size_1085_sets_91_k_20_correlated.txt | D5: 700 | E5: 2175.0 | F5: 0.00
A6: scenario 1 | B6: correlated | C6: scen_1id_10_objs_800_size_1240_sets_94_k_18_correlated.txt | D6: 800 | E6: 2342.0 | F6: 0.00
A7: scenario 1 | B7: correlated | C7: scen_1id_1_objs_1000_size_1550_sets_89_k_18_correlated.txt | D7: 1000 | E7: 2602.0 | F7: 0.00
A8: scenario 1 | B8: correlated | C8: scen_1id_1_objs_300_size_465_sets_74_k_20_correlated.txt | D8: 300 | E8: 1.1751111e+15 | F8: 0.00
A9: scenario 1 | B9: correlated | C9: scen_1id_1_objs_500_size_775_sets_78_k_20_correlated.txt | D9: 500 | E9: 1732.0 | F9: 0.00
A10: scenario 1 | B10: correlated | C10: scen_1id_1_objs_700_size_1085_sets_82_k_20_correlated.txt | D10: 700 | E10: 2085.0 | F10: 0.00
A11: scenario 1 | B11: correlated | C11: scen_1id_1_objs_800_size_1240_sets_93_k_18_correlated.txt | D11: 800 | E11: 2332.0 | F11: 0.00
A12: scenario 1 | B12: correlated | C12: scen_1id_2_objs_1000_size_1550_sets_96_k_18_correlated.txt | D12: 1000 | E12: 2672.0 | F12: 0.00
A13: scenario 1 | B13: correlated | C13: scen_1id_2_objs_300_size_465_sets_79_k_20_correlated.txt | D13: 300 | E13: 1258.0 | F13: 0.00
A14: scenario 1 | B14: correlated | C14: scen_1id_2_objs_500_size_775_sets_83_k_20_correlated.txt | D14: 500 | E14: 1771.0 | F14: 0.00
A15: scenario 1 | B15: correlated | C15: scen_1id_2_objs_700_size_1085_sets_102_k_20_correlated.txt | D15: 700 | E15: 2282.0 | F15: 0.00
A16: scenario 1 | B16: correlated | C16: scen_1id_2_objs_800_size_1240_sets_100_k_18_correlated.txt | D16: 800 | E16: 2402.0 | F16: 0.00
A17: scenario 1 | B17: correlated | C17: scen_1id_3_objs_1000_size_1550_sets_89_k_18_correlated.txt | D17: 1000 | E17: 2602.0 | F17: 0.00
A18: scenario 1 | B18: correlated | C18: scen_1id_3_objs_300_size_465_sets_76_k_20_correlated.txt | D18: 300 | E18: 1.21575e+16 | F18: 0.00
A19: scenario 1 | B19: correlated | C19: scen_1id_3_objs_500_size_775_sets_84_k_20_correlated.txt | D19: 500 | E19: 1.7764615e+16 | F19: 0.00
A20: scenario 1 | B20: correlated | C20: scen_1id_3_objs_700_size_1085_sets_86_k_20_correlated.txt | D20: 700 | E20: 2125.0 | F20: 0.00
A21: scenario 1 | B21: correlated | C21: scen_1id_3_objs_800_size_1240_sets_92_k_18_correlated.txt | D21: 800 | E21: 2.317e+16 | F21: 0.00
A22: scenario 1 | B22: correlated | C22: scen_1id_4_objs_1000_size_1550_sets_90_k_18_correlated.txt | D22: 1000 | E22: 2612.0 | F22: 0.00
A23: scenario 1 | B23: correlated | C23: scen_1id_4_objs_300_size_465_sets_78_k_20_correlated.txt | D23: 300 | E23: 1.2013333e+16 | F23: 0.00
A24: scenario 1 | B24: correlated | C24: scen_1id_4_objs_500_size_775_sets_81_k_20_correlated.txt | D24: 500 | E24: 1.7564211e+15 | F24: 0.00
A25: scenario 1 | B25: correlated | C25: scen_1id_4_objs_700_size_1085_sets_82_k_20_correlated.txt | D25: 700 | E25: 2085.0 | F25: 0.00
A26: scenario 1 | B26: correlated | C26: scen_1id_4_objs_800_size_1240_sets_99_k_18_correlated.txt | D26: 800 | E26: 2392.0 | F26: 0.00
A27: scenario 1 | B27: correlated | C27: scen_1id_5_objs_1000_size_1550_sets_84_k_18_correlated.txt | D27: 1000 | E27: 2542.0 | F27: 0.00
A28: scenario 1 | B28: correlated | C28: scen_1id_5_objs_300_size_465_sets_75_k_20_correlated.txt | D28: 300 | E28: 1200.0 | F28: 0.00
A29: scenario 1 | B29: correlated | C29: scen_1id_5_objs_500_size_775_sets_83_k_20_correlated.txt | D29: 500 | E29: 1778.0 | F29: 0.00
A30: scenario 1 | B30: correlated | C30: scen_1id_5_objs_700_size_1085_sets_80_k_20_correlated.txt | D30: 700 | E30: 2065.0 | F30: 0.00
A31: scenario 1 | B31: correlated | C31: scen_1id_5_objs_800_size_1240_sets_91_k_18_correlated.txt | D31: 800 | E31: 2312.0 | F31: 0.00
A32: scenario 1 | B32: correlated | C32: scen_1id_6_objs_1000_size_1550_sets_91_k_18_correlated.txt | D32: 1000 | E32: 2622.0 | F32: 0.00
A33: scenario 1 | B33: correlated | C33: scen_1id_6_objs_300_size_465_sets_78_k_20_correlated.txt | D33: 300 | E33: 1.2083333e+16 | F33: 0.00
A34: scenario 1 | B34: correlated | C34: scen_1id_6_objs_500_size_775_sets_87_k_20_correlated.txt | D34: 500 | E34: 1819625 | F34: 0.00
A35: scenario 1 | B35: correlated | C35: scen_1id_6_objs_700_size_1085_sets_92_k_20_correlated.txt | D35: 700 | E35: 2180.0 | F35: 0.00
A36: scenario 1 | B36: correlated | C36: scen_1id_6_objs_800_size_1240_sets_87_k_18_correlated.txt | D36: 800 | E36: 2272.0 | F36: 0.00
A37: scenario 1 | B37: correlated | C37: scen_1id_7_objs_1000_size_1550_sets_96_k_18_correlated.txt | D37: 1000 | E37: 2672.0 | F37: 0.00
A38: scenario 1 | B38: correlated | C38: scen_1id_7_objs_300_size_465_sets_78_k_20_correlated.txt | D38: 300 | E38: 1.2366667e+16 | F38: 0.00
A39: scenario 1 | B39: correlated | C39: scen_1id_7_objs_500_size_775_sets_83_k_20_correlated.txt | D39: 500 | E39: 1779.0 | F39: 0.00
A40: scenario 1 | B40: correlated | C40: scen_1id_7_objs_700_size_1085_sets_88_k_20_correlated.txt | D40: 700 | E40: 2145.0 | F40: 0.00
...

Sheet Analysis
A1: DP vs Gurobi — Comparison Analysis
A3: 1. OBJECTIVE VALUE CHECK
A4: Total instances compared: | B4: =COUNTA(results_dp!A2:A601) -> 600
A5: Mismatches found: | B5: {=SUMPRODUCT((results_dp!E2:E601<>results_gurobi!E2:E601)*1)} -> 0
A6: Verdict: | B6: =IF(B5=0,"✅ All objective values are identical","⚠️ "&B5&" mismatches found") -> ✅ All objective values are identical
A8: 2. OVERALL RUNTIME COMPARISON
A9: Solver | B9: Mean (s) | C9: Median (s) | D9: Std Dev (s) | E9: Min (s) | F9: Max (s) | G9: N
A10: DP | B10: =AVERAGE(results_dp!F2:F601) -> 3.9850167 | C10: =MEDIAN(results_dp!F2:F601) -> 2.205 | D10: =STDEV(results_dp!F2:F601) -> 4.9130503 | E10: =MIN(results_dp!F2:F601) -> 0.06 | F10: =MAX(results_dp!F2:F601) -> 24.01 | G10: =COUNTA(results_dp!F2:F601) -> 600
A11: Gurobi | B11: =AVERAGE(results_gurobi!F2:F601) -> 0.0089833333 | C11: =MEDIAN(results_gurobi!F2:F601) -> 0.01 | D11: =STDEV(results_gurobi!F2:F601) -> 0.0047085035 | E11: =MIN(results_gurobi!F2:F601) -> 0 | F11: =MAX(results_gurobi!F2:F601) -> 0.05 | G11: =COUNTA(results_gurobi!F2:F601) -> 600
A12: Speedup (DP/Gurobi) | B12: =B10/B11 -> 443.60111 | C12: =C10/C11 -> 220.5
A14: 3. RUNTIME BY SCENARIO
A15: Scenario | B15: Count | C15: DP Mean (s) | D15: DP Median (s) | E15: Gurobi Mean (s) | F15: Gurobi Median (s) | G15: Speedup Mean | H15: Speedup Median
A16: scenario 1 | B16: =COUNTIF(results_dp!A2:A601,A16) -> 150 | C16: =AVERAGEIF(results_dp!A2:A601,A16,results_dp!F2:F601) -> 1.9146 | D16: {=MEDIAN(IF(results_dp!A2:A601=A16,results_dp!F2:F601))} -> 1.65 | E16: =AVERAGEIF(results_gurobi!A2:A601,A16,results_gurobi!F2:F601) -> 0.0097333333 | F16: {=MEDIAN(IF(results_gurobi!A2:A601=A16,results_gurobi!F2:F601))} -> 0.01 | G16: =C16/E16 -> 196.70548 | H16: =D16/F16 -> 165
A17: scenario 2 | B17: =COUNTIF(results_dp!A2:A601,A17) -> 150 | C17: =AVERAGEIF(results_dp!A2:A601,A17,results_dp!F2:F601) -> 3.3066667 | D17: {=MEDIAN(IF(results_dp!A2:A601=A17,results_dp!F2:F601))} -> 3.67 | E17: =AVERAGEIF(results_gurobi!A2:A601,A17,results_gurobi!F2:F601) -> 0.0082 | F17: {=MEDIAN(IF(results_gurobi!A2:A601=A17,results_gurobi!F2:F601))} -> 0.01 | G17: =C17/E17 -> 403.25203 | H17: =D17/F17 -> 367
A18: scenario 3 | B18: =COUNTIF(results_dp!A2:A601,A18) -> 150 | C18: =AVERAGEIF(results_dp!A2:A601,A18,results_dp!F2:F601) -> 3.0452667 | D18: {=MEDIAN(IF(results_dp!A2:A601=A18,results_dp!F2:F601))} -> 2.07 | E18: =AVERAGEIF(results_gurobi!A2:A601,A18,results_gurobi!F2:F601) -> 0.0093333333 | F18: {=MEDIAN(IF(results_gurobi!A2:A601=A18,results_gurobi!F2:F601))} -> 0.01 | G18: =C18/E18 -> 326.27857 | H18: =D18/F18 -> 207
A19: scenario 4 | B19: =COUNTIF(results_dp!A2:A601,A19) -> 150 | C19: =AVERAGEIF(results_dp!A2:A601,A19,results_dp!F2:F601) -> 7.6735333 | D19: {=MEDIAN(IF(results_dp!A2:A601=A19,results_dp!F2:F601))} -> 5.42 | E19: =AVERAGEIF(results_gurobi!A2:A601,A19,results_gurobi!F2:F601) -> 0.0086666667 | F19: {=MEDIAN(IF(results_gurobi!A2:A601=A19,results_gurobi!F2:F601))} -> 0.01 | G19: =C19/E19 -> 885.40769 | H19: =D19/F19 -> 542
A21: 4. RUNTIME BY CORRELATION TYPE
A22: Correlation Type | B22: Count | C22: DP Mean (s) | D22: DP Median (s) | E22: Gurobi Mean (s) | F22: Gurobi Median (s) | G22: Speedup Mean | H22: Speedup Median
A23: correlated | B23: =COUNTIF(results_dp!B2:B601,A23) -> 200 | C23: =AVERAGEIF(results_dp!B2:B601,A23,results_dp!F2:F601) -> 3.9877 | D23: {=MEDIAN(IF(results_dp!B2:B601=A23,results_dp!F2:F601))} -> 2.295 | E23: =AVERAGEIF(results_gurobi!B2:B601,A23,results_gurobi!F2:F601) -> 0.00955 | F23: {=MEDIAN(IF(results_gurobi!B2:B601=A23,results_gurobi!F2:F601))} -> 0.01 | G23: =C23/E23 -> 417.56021 | H23: =D23/F23 -> 229.5
A24: fully-correlated | B24: =COUNTIF(results_dp!B2:B601,A24) -> 200 | C24: =AVERAGEIF(results_dp!B2:B601,A24,results_dp!F2:F601) -> 3.9501 | D24: {=MEDIAN(IF(results_dp!B2:B601=A24,results_dp!F2:F601))} -> 2.14 | E24: =AVERAGEIF(results_gurobi!B2:B601,A24,results_gurobi!F2:F601) -> 0.0091 | F24: {=MEDIAN(IF(results_gurobi!B2:B601=A24,results_gurobi!F2:F601))} -> 0.01 | G24: =C24/E24 -> 434.07692 | H24: =D24/F24 -> 214
A25: not-correlated | B25: =COUNTIF(results_dp!B2:B601,A25) -> 200 | C25: =AVERAGEIF(results_dp!B2:B601,A25,results_dp!F2:F601) -> 4.01725 | D25: {=MEDIAN(IF(results_dp!B2:B601=A25,results_dp!F2:F601))} -> 2.255 | E25: =AVERAGEIF(results_gurobi!B2:B601,A25,results_gurobi!F2:F601) -> 0.0083 | F25: {=MEDIAN(IF(results_gurobi!B2:B601=A25,results_gurobi!F2:F601))} -> 0.01 | G25: =C25/E25 -> 484.00602 | H25: =D25/F25 -> 225.5
A27: 5. RUNTIME BY SCENARIO × CORRELATION TYPE
A29: DP Mean Runtime (s)
B30: correlated | C30: fully-correlated | D30: not-correlated
A31: scenario 1 | B31: =AVERAGEIFS(results_dp!F2:F601,results_dp!A2:A601,A31,results_dp!B2:B601,B30) -> 1.8556 | C31: =AVERAGEIFS(results_dp!F2:F601,results_dp!A2:A601,A31,results_dp!B2:B601,C30) -> 1.945 | D31: =AVERAGEIFS(results_dp!F2:F601,results_dp!A2:A601,A31,results_dp!B2:B601,D30) -> 1.9432
A32: scenario 2 | B32: =AVERAGEIFS(results_dp!F2:F601,results_dp!A2:A601,A32,results_dp!B2:B601,B30) -> 3.2406 | C32: =AVERAGEIFS(results_dp!F2:F601,results_dp!A2:A601,A32,results_dp!B2:B601,C30) -> 3.287 | D32: =AVERAGEIFS(results_dp!F2:F601,results_dp!A2:A601,A32,results_dp!B2:B601,D30) -> 3.3924
A33: scenario 3 | B33: =AVERAGEIFS(results_dp!F2:F601,results_dp!A2:A601,A33,results_dp!B2:B601,B30) -> 3.1104 | C33: =AVERAGEIFS(results_dp!F2:F601,results_dp!A2:A601,A33,results_dp!B2:B601,C30) -> 2.8956 | D33: =AVERAGEIFS(results_dp!F2:F601,results_dp!A2:A601,A33,results_dp!B2:B601,D30) -> 3.1298
A34: scenario 4 | B34: =AVERAGEIFS(results_dp!F2:F601,results_dp!A2:A601,A34,results_dp!B2:B601,B30) -> 7.7442 | C34: =AVERAGEIFS(results_dp!F2:F601,results_dp!A2:A601,A34,results_dp!B2:B601,C30) -> 7.6728 | D34: =AVERAGEIFS(results_dp!F2:F601,results_dp!A2:A601,A34,results_dp!B2:B601,D30) -> 7.6036
A36: Gurobi Mean Runtime (s)
B37: correlated | C37: fully-correlated | D37: not-correlated
A38: scenario 1 | B38: =AVERAGEIFS(results_gurobi!F2:F601,results_gurobi!A2:A601,A38,results_gurobi!B2:B601,B37) -> 0.0104 | C38: =AVERAGEIFS(results_gurobi!F2:F601,results_gurobi!A2:A601,A38,results_gurobi!B2:B601,C37) -> 0.0092 | D38: =AVERAGEIFS(results_gurobi!F2:F601,results_gurobi!A2:A601,A38,results_gurobi!B2:B601,D37) -> 0.0096
A39: scenario 2 | B39: =AVERAGEIFS(results_gurobi!F2:F601,results_gurobi!A2:A601,A39,results_gurobi!B2:B601,B37) -> 0.0088 | C39: =AVERAGEIFS(results_gurobi!F2:F601,results_gurobi!A2:A601,A39,results_gurobi!B2:B601,C37) -> 0.0082 | D39: =AVERAGEIFS(results_gurobi!F2:F601,results_gurobi!A2:A601,A39,results_gurobi!B2:B601,D37) -> 0.0076
A40: scenario 3 | B40: =AVERAGEIFS(results_gurobi!F2:F601,results_gurobi!A2:A601,A40,results_gurobi!B2:B601,B37) -> 0.0098 | C40: =AVERAGEIFS(results_gurobi!F2:F601,results_gurobi!A2:A601,A40,results_gurobi!B2:B601,C37) -> 0.01 | D40: =AVERAGEIFS(results_gurobi!F2:F601,results_gurobi!A2:A601,A40,results_gurobi!B2:B601,D37) -> 0.0082
A41: scenario 4 | B41: =AVERAGEIFS(results_gurobi!F2:F601,results_gurobi!A2:A601,A41,results_gurobi!B2:B601,B37) -> 0.0092 | C41: =AVERAGEIFS(results_gurobi!F2:F601,results_gurobi!A2:A601,A41,results_gurobi!B2:B601,C37) -> 0.009 | D41: =AVERAGEIFS(results_gurobi!F2:F601,results_gurobi!A2:A601,A41,results_gurobi!B2:B601,D37) -> 0.0078
A43: Speedup (DP/Gurobi)
B44: correlated | C44: fully-correlated | D44: not-correlated
A45: scenario 1 | B45: =B31/B38 -> 178.42308 | C45: =C31/C38 -> 211.41304 | D45: =D31/D38 -> 202.41667
A46: scenario 2 | B46: =B32/B39 -> 368.25 | C46: =C32/C39 -> 400.85366 | D46: =D32/D39 -> 446.36842
A47: scenario 3 | B47: =B33/B40 -> 317.38776 | C47: =C33/C40 -> 289.56 | D47: =D33/D40 -> 381.68293
A48: scenario 4 | B48: =B34/B41 -> 841.76087 | C48: =C34/C41 -> 852.53333 | D48: =D34/D41 -> 974.82051
...
